Workbook

Sheet REPARTO DE PESOS ESTIMADO
A1: REPARTO DE PESOS
F4: EJE DELANTERO | J4: EJE TRASERO
H6: Kg | L6: Kg
F7: TARA eje delantero | H7: 556 | J7: TARA eje trasero | L7: 514
F8: Peso elem. Desmontados | J8: Peso elem. Desmontados
F9: Peso elem. Montados | J9: Peso elem. Montados
F10: Peso ocupantes sobre eje | H10: =(2/3)*D27 -> 100 | J10: Peso ocupantes sobre eje | L10: =D28+D27/3 -> 200
J11: Carga útil (equipaje) | L11: =D31-D23-(D25+D26-1)*75 -> 50
F12: SUMATORIO | H12: =H7-H8+H9+H10 -> 656 | J12: Carga enganche
F14: MMA EJE DELANTERO | H14: =D29 -> 680 | J14: SUMATORIO | L14: =L7-L8+L9+L10+L11+L12 -> 764
F16: ¿CUMPLE? | H16: =H12 -> 656 | J16: MMA EJE TRASERO | L16: =D30 -> 790
J18: ¿CUMPLE? | L18: =L14 -> 764
A19: MASAS DEL VEHICULO
D21: Kg
A22: TARA DEL VEHÍCULO | D22: 1070
A23: MOM | D23: =D22+75 -> 1145
A24: PESO DEL CONDUCTOR | D24: 75
A25: Nº PLAZAS DELANTERAS | D25: 2
A26: Nº PLAZAS TRASERAS | D26: 2
A27: PESO OCUPANTES PLAZAS DELANTERAS | D27: =D25*75 -> 150
A28: PESO OCUPANTES PLAZAS TRASERAS | D28: =D26*75 -> 150
A29: MMA EJE DELANTERO | D29: 680
A30: MMA EJE TRASERO | D30: 790
A31: MMA VEHÍCULO | D31: 1420

Sheet CALCULOS VARIOS POTENCIA
B1: MOTOR 4 TIEMPOS | M1: MOTOR 2 TIEMPOS
A4: La entrada de datos en las casillas en rojo, las fórmulas están en las casillas en verde (RESULTADOS) | M4: A: cuando sabes el número de cilindros y la cilindrada obtenida con el diámetro y la carrera
A5: A: cuando sabes el número de cilindros y la cilindrada obtenida con el diámetro y la carrera | M5: DIÁMETRO | N5: 7.4
A6: DIÁMETRO | B6: 9.047 | M6: CARRERA | N6: 7 | P6: POT. FISCAL | Q6: =0.11*POWER(0.785*N5*N5*N6,0.6)*N7 -> 6.7527607
A7: CARRERA | B7: 8.89 | D7: POT. FISCAL | E7: =0.08*POWER(0.785*B6*B6*B7,0.6)*B8 -> 14.428405 | G7: NOTA | M7: N CILINDROS | N7: 2
A8: N CILINDROS | B8: 4 | O8: CILINDRADA | P8: =PI( )*N5*N5*N6*N7/4 -> 602.11765
C9: CILINDRADA | D9: =PI( )*B6*B6*B7*B8/4 -> 2285.9189
M10: B: cuando sabes el número de cilindros y la cilindrada directamente
A11: B: cuando sabes el número de cilindros y la cilindrada directamente | M11: N CILINDROS | N11: 2
A12: N CILINDROS | B12: 4 | M12: CILINDRADA | N12: 602
A13: CILINDRADA | B13: 2286 | P13: POT. FISCAL | Q13: =0.08*POWER(0.785*N12*4/PI()/N11,0.6)*N11 -> 4.910523
D14: POT. FISCAL | E14: =0.08*POWER(0.785*B13*4/PI()/B12,0.6)*B12 -> 14.428713
M15: C: cuando tienes la cilindrada y la potencia fiscal
A16: C: cuando tienes la cilindrada y la potencia fiscal | M16: POT FISCAL | N16: 4.91
A17: POT FISCAL | B17: 45.76 | M17: CILINDRADA | N17: 602
A18: CILINDRADA | B18: 11940 | P18: N CILINDROS | Q18: =POWER((POWER($B$14/0.08,1/0.6))*PI()/0.785/$B$15/4,0.6/0.4) -> #DIV/0!
D19: N CILINDROS | E19: =POWER((POWER($B$17/0.08,1/0.6))*PI()/0.785/$B$18/4,0.6/0.4) -> 6.0022478
M20: D: resulta imposible determinar cual es el diámetro y la carrera si solo sabemos la cilindrada y el número de cilindros.
A21: D: resulta imposible determinar cual es el diámetro y la carrera si solo sabemos la cilindrada y el número de cilindros.
B25: CÁLCULO POTENCIA DE UN MOTOR

Sheet CAMBIO DE RUEDAS
A1: VARIACIÓN DEL NEUMÁTICO
C7: ORIGINAL | I7: REFORMA
O8: VARIACION %
O10: =(J18*100/D18)-100 -> 0.12759171
C11: ANCHO | D11: PERFIL | E11: RADIO | F11: INDICE CARGA | G11: INDICE VEL | I11: ANCHO | J11: PERFIL | K11: RADIO | L11: INDICE CARGA | M11: INDICE VEL
A12: CENTIMETROS | C12: 205 | D12: 60 | E12: 15 | I12: 245 | J12: 40 | K12: 17
D16: MEDIDA | J16: MEDIDA | O16: LÍMITE 10% | S16: VARIACIÓN ALTURA (cm)
D18: =E12*25.4+2*(C12*D12/100) -> 627 | G18: mm | J18: =K12*25.4+2*(I12*J12/100) -> 627.8 | M18: mm | O18: =D18*1.1 -> 689.7 | S18: =((J18-D18)/2)/10 -> 0.04
C23: ORIGINAL | I23: REFORMA | O23: MEDIDA
O25: =D34*1.1 -> 0
C27: ANCHO | D27: PERFIL | E27: RADIO | F27: INDICE CARGA | G27: INDICE VEL | I27: ANCHO | J27: PERFIL | K27: RADIO | L27: INDICE CARGA | M27: INDICE VEL
A28: PULGADAS | I28: 33 | J28: 10.5 | K28: 15
D32: MEDIDA | J32: MEDIDA | Q32: 799.3 | S32: 100
Q33: 872.8 | U33: =Q33*S32/Q32 -> 109.19555
D34: =C28*25.4 -> 0 | J34: =I28*25.4 -> 838.2
A39: criterios de equivalencia:
A41: Índice de capacidad de carga igual o superior.
A42: Código de categoría de velocidad igual o superior.
A43: Igual diámetro exterior con una tolerancia de ±3 %.
A44: Que el perfil de la llanta de montaje sea el correspondiente al neumático.
A46: SI NO SON EQUIVALENTES Y SU DIFERENCIA ES SUPERIOR AL 10%
A48: PRUEBA DE FRENADO | D48: PRUEBAS | E48: CERTIFICADO
A49: PRUEBA DE VELOCIMETRO | D49: 675+IVA | E49: 199+IVA
A50: PRUEBA DE RUIDO
A51: PRUEBA DE DIRECCIÓN
A54: SOLAMENTE PRUEBA DE FRENADO | D54: PRUEBAS | E54: CERTIFICADO
D55: 250+IVA | E55: 199+IVA

Sheet TOTALES
B1: TOTALES
C6: MOM ANTES DE LA REFORMA | D6: 2090 | F6: AUMENTO DE PESO | H6: =C12-D6 -> -115
C8: Total | D8: Delantero | E8: Trasera
B9: Tara Vehículo | C9: =E9+D9 -> 1900 | D9: 1000 | E9: 900
B12: Masa Real | C12: =C9+75 -> 1975
A15: Ocupantes adic. | B15: 3 | C15: Carga vertical acopl | D15: 80 | F15: MMR | G15: 6220
A16: Total Kg ocup. Adicion. | B16: =75*B15 -> 225 | C16: Resto ocup. Del | D16: 2
A17: MMA | B17: 2000 | C17: ocupantes 2ª fila | D17: 2 | F17: =G15*0.04 -> 248.8
A18: MMA eje 1 | B18: 1500 | C18: ocupantes 3ªfila | D18: 1
A19: MMA eje 2 | B19: 1000 | C19: peso ocupante | D19: 75
A20: Carga útil | B20: =B17-C12-B16 -> -200
C29: mm dibujo | E29: mm en real
A30: dist. Entre ejes | C30: 1713 | E30: 3665
A31: Conductor | C31: 509 | E31: 900
A32: Ocup. Delant | C32: =C31 -> 509 | E32: =E31 -> 900
A33: Ocup. 2ª fila | C33: 950 | E33: 150
A34: Ocup. 3ª fila | C34: 0 | E34: 75
A35: Carga útil | C35: 2000 | E35: 3538
A36: Carga vertical | C36: 2258 | E36: 80
B40: Distancia entre ejes | C40: 4035
C42: Total | D42: Delantero | E42: Trasero
A43: Distancia CDG a eje delantero (mm) | B43: Tara del vehículo tras la reforma | C43: =C9 -> 1900 | D43: =D9 -> 1000 | E43: =E9 -> 900 | K43: Elemento | L43: Peso (Kg) | M43: Nº Tornillos | N43: Métrica | O43: Área útil | P43: Área total
A44: =E31 -> 900 | B44: Conductor | C44: 75 | D44: =C44-E44 -> 58.271375 | E44: =C44*A44/$C$40 -> 16.728625 | L44: 20 | M44: 4 | N44: 0.075 | P44: =N44*L44 -> 1.5 | Q44: 10
B45: Masa Real | C45: =C43+C44 -> 1975 | D45: =D43+D44 -> 1058.2714 | E45: =E43+E44 -> 916.72862
A46: =A44 -> 900 | B46: Ocup. Delant | C46: =D16*$D$19 -> 150 | D46: =C46-E46 -> 116.54275 | E46: =C46*A46/$C$40 -> 33.457249
A47: =E33 -> 150 | B47: Ocup. 2ª fila | C47: =D17*$D$19 -> 150 | D47: =C47-E47 -> 144.42379 | E47: =C47*A47/$C$40 -> 5.5762082
A48: =E34 -> 75 | B48: Ocup. 3ª fila | C48: 0 | D48: =C48-E48 -> 0 | E48: =C48*A48/$C$40 -> 0
A49: 3620 | B49: Carga útil | C49: =B20 -> -200 | D49: =C49-E49 -> -20.570012 | E49: =C49*A49/$C$40 -> -179.42999
B50: Suma de cargas | C50: =SUM(C45:C49) -> 2075 | D50: =SUM(D45:D49) -> 1298.6679 | E50: =SUM(E45:E49) -> 776.33209
B51: MMA | C51: =B17 -> 2000 | D51: =B18 -> 1500 | E51: =B19 -> 1000
A54: Distancia CDG a eje delantero (mm) | B54: Tara del vehículo tras la reforma | C54: =C43 -> 1900 | D54: =D43 -> 1000 | E54: =E43 -> 900
A55: =E31 -> 900 | B55: Conductor | C55: =C44 -> 75 | D55: =C55-E55 -> 58.271375 | E55: =C55*A55/$C$40 -> 16.728625
B56: Masa Real | C56: =C45 -> 1975 | D56: =D45 -> 1058.2714 | E56: =E45 -> 916.72862
A57: =E32 -> 900 | B57: Ocup. Delant | C57: =C46 -> 150 | D57: =C57-E57 -> 116.54275 | E57: =C57*A57/$C$40 -> 33.457249
A58: =E33 -> 150 | B58: Ocup. 2ª fila | C58: =C47 -> 150 | D58: =C58-E58 -> 144.42379 | E58: =C58*A58/$C$40 -> 5.5762082
A59: =E34 -> 75 | B59: Ocup. 3ª fila | C59: =C48 -> 0 | D59: =C59-E59 -> 0 | E59: =C59*A59/$C$40 -> 0
A60: =E35 -> 3538 | B60: Carga útil | C60: =C49-C61 -> -280 | D60: =C60-E60 -> -34.488228 | E60: =C60*A60/$C$40 -> -245.51177
A61: =E36 -> 80 | B61: Carga vert. Acopl. | C61: =D15 -> 80 | D61: =C61-E61 -> 78.413879 | E61: =C61*A61/$C$40 -> 1.5861214
B62: Suma de cargas | C62: =SUM(C56:C61) -> 2075 | D62: =SUM(D56:D61) -> 1363.1636 | E62: =SUM(E56:E61) -> 711.83643
B63: MMA | C63: =C51 -> 2000 | D63: =D51 -> 1500 | E63: =E51 -> 1000

Sheet SUSPENSION
A1: CÁLCULO JUSTIFICATIVOS SUSTITUCIÓN MUELLES
A4: Las MMA a considerar en los cálculos son las siguientes
B6: MMA A CONSIDERAR EN CÁLCULOS
B7: MTMA/MMA (Kg) | E7: =TOTALES!B17 -> 2000
B8: MTMA/MMA eje 1 | E8: =TOTALES!B18 -> 1500
B9: MTMA/MMA eje 2 | E9: =TOTALES!B19 -> 1000
A11: Características del material NORMALMENTE ACERO EN 12070-2 SiCr
A13: Características muelle (Acero EN 12070-2 SiCr) | D13: Kg/mm2 | E13: Mpa
A14: Resistencia mecánica (Rm) | D14: 204 | E14: 2001.24
A15: Resistencia elástica (Re) | D15: 176 | E15: 1726.56
A16: Resistencia práctica del aero a cizalla/cortadura (Rc) | D16: 114 | E16: 1118.34
A18: Módulo de elasticidad al cizallamiento | D18: 8104 | E18: 79500.24
A19: Incremento del alargamiento mínimo (A) | D19: 0.05
A22: Características del geométricas, medidas sobre el muelle (EJE DELANTERO)
A24: Características geométricas muelles delanteros | D24: mm
A25: Diámetro exterior (Dext) | D25: 105
A26: Diámetro interior (Dint) | D26: =D25-(2*D28) -> 75
A27: Diámetro medio (Dm) | D27: =(D25+D26)/2 -> 90
A28: Diámetro de espira (De) | D28: 15
A29: Longitud libre (Lmax)=L0 | D29: 470
A30: Número de espiras (n) (empezamos por 0) | D30: 7
A31: Curvatura ( C ) | D31: =D27/D28 -> 6
A32: Rigidez (K) N/mm | D32: =((((D28/1000)^4)*E18*1000000)/(8*((D27/1000)^3)*D30))/1000 -> 98.586607
B34: CÁLCULO DEL ESFUERZO MÁXIMO CORTANTE (EMC)
B37: Esf. Máx. Cortante 1 muelle (N) | C37: Esf. Máx. Cortante eje delantero (N) | D37: Coeficiente de seguridad K>1
B38: =PI()*((D28/1000)^3*E16*1000000)/(8*(D27/1000)) -> 16468.916 | C38: =B38*2 -> 32937.832 | D38: =C38/(E8*9.81) -> 2.2383848
B40: CÁLCULO LA CARGA MÁX (Q) EN FUNCIÓN DE LA FLECHA DEL MUELLE
B43: Long. Mín muelle (mm) | C43: Flecha del resorte (mm) | D43: Carga máx en función de la flecha muelle (Q) (N) | E43: Carga máx en función de la flecha eje 1 (Qdel) (Q) | F43: Coef. Seguridad K(Q) > 1
B44: =D30*D28 -> 105 | C44: =D29-B44 -> 365 | D44: =((C44/1000)*E18*1000000*((D28/1000)^4))/(64*D30*((D27/1000)/2)^3) -> 35984.112 | E44: =2*D44 -> 71968.223 | F44: =E44/(E8*9.81) -> 4.8908069
A48: Fuerza máx eje delantero (N) | B48: Factor de BergsträsserKb | C48: Esfuerzo del muelle (T) mPA | D48: Coeficiente de seguridad Kt>1
A49: =(E8*9.81)/2 -> 7357.5 | B49: =((4*D31)+2)/((4*D31)-3) -> 1.2380952 | C49: =(B49*8*A49*D27)/(PI()*(D28)^3) -> 618.57615 | D49: =E16/C49 -> 1.8079262
A54: Características del geométricas, medidas sobre el muelle (EJE TRASERO)
A56: Características geométricas muelles traseros | D56: mm
A57: Diámetro exterior (Dext) | D57: 106
A58: Diámetro interior (Dint) | D58: =D57-(2*D60) -> 68
A59: Diámetro medio (Dm) | D59: =(D57+D58)/2 -> 87
A60: Diámetro de espira (De) | D60: 19
A61: Longitud libre (Lmax)=L0 | D61: 465
A62: Número de espiras (n) (empezamos por 0) | D62: 8
A63: Curvatura ( C ) | D63: =D59/D60 -> 4.5789474
...

Sheet BALLESTAS
A1: CÁLCULO JUSTIFICATIVOS SUSTITUCIÓN BALLESTAS
A4: Las MMA a considerar en los cálculos son las siguientes
B6: CARACTERÍSTICAS DEL VEHÍCULO
B7: MTMA/MMA (Kg) | E7: =TOTALES!B17 -> 2000
B8: MTMA/MMA eje 1 | E8: =TOTALES!B18 -> 1500
B9: MTMA/MMA eje 2 | E9: =TOTALES!B19 -> 1000
A39: CÁLCULO DE LA BALLESTA EN EL EJE 1:
A41: Número de hojas: N= | C41: 7
A42: Ancho de la hoja b= | C42: 50 | D42: mm
A43: Espesor de la hoja e= | C43: 8 | D43: mm
A44: Longitud total ballesta 2L= | C44: 800 | D44: mm
A45: Esfuerzo de la flexión σ= | C45: 60 | D45: Kg/mm2
B49: F= | C49: =C41*C42*(C43^2)*C45/(6*C44/2) -> 560 | D49: Kg
B55: 2F= | C55: =C49*2 -> 1120 | D55: Kg
A59: CÁLCULO DE LA BALLESTA EN EL EJE 2:
A61: Número de hojas: N= | C61: 9
A62: Ancho de la hoja b= | C62: 60 | D62: mm
A63: Espesor de la hoja e= | C63: 12 | D63: mm
A64: Longitud total ballesta 2L= | C64: 750 | D64: mm
A65: Esfuerzo de la flexión σ= | C65: 60 | D65: Kg/mm2
B69: F= | C69: =C61*C62*(C63^2)*C65/(6*C64/2) -> 2073.6 | D69: Kg
B75: 2F= | C75: =C69*2 -> 4147.2 | D75: Kg

Sheet TACOS EN SUSPENSION
A1: TACOS DE NYLON
B7: CARACTERÍSTICAS DEL VEHÍCULO Y TACOS
B8: MTMA/MMA (Kg) | E8: =TOTALES!B17 -> 2000
B9: MTMA/MMA eje 1 | E9: =TOTALES!B18 -> 1500
B10: MTMA/MMA eje 2 | E10: =TOTALES!B19 -> 1000
B11: PUNTOS DE APOYO | E11: 2
B12: Resistencia a compresión del nylon (Kg/cm2) | E12: 917
B14: EJE DELANTERO
B16: Peso a soportar por taco (Kg)= | D16: MMA/MMTA | F16: = | G16: =E9/E11 -> 750
D17: Nº puntos de apoyo
B20: DIMENSIONES DEL TACO
B21: Diámetro (cm) | D21: 9
B22: Radio (cm) | D22: =D21/2 -> 4.5
B23: Espesor (cm) | D23: 4.5
B24: Superficie (cm2) | D24: =3.14*D22*D22 -> 63.585
B25: Res. Maxima a compresión (Kg) | D25: =D24*E12 -> 58307.445
B28: EJE TRASERO
B30: Peso a soportar por taco (Kg)= | D30: MMA/MMTA | F30: = | G30: =E10/E11 -> 500
D31: Nº puntos de apoyo
B34: DIMENSIONES DEL TACO
B35: Diámetro (cm) | D35: 9
B36: Radio (cm) | D36: =D35/2 -> 4.5
B37: Espesor (cm) | D37: 4.5
B38: Superficie (cm2) | D38: =3.14*D36*D36 -> 63.585
B39: Res. Maxima a compresión (Kg) | D39: =D38*E12 -> 58307.445

Sheet ALETINES
C2: ALETINES
A5: CARACTERÍSTICAS DE LA PIEZA | D5: SUJECIÓN
A6: Peso de la pieza en Kg | C6: 0.5 | D6: nº tornillos | F6: 18
A7: Anchura de la pieza en m | C7: 0.4 | D7: Métrica | F7: 4
A8: Altura de la pieza en m | C8: 0.4 | D8: Calidad | F8: 8.8
A9: Superficie frontal m2 | C9: =C7*C8 -> 0.16 | D9: As( Sección resistente) | F9: 11.33
A10: Coef. aerodinámico | C10: 0.82 | D10: Res. Tracción Mín tornillo 8,8 (Kg/mm2) | F10: 80
A13: CARACTERÍSTICAS PARA FUERZA PRODUCIDA POR PRESIÓN DEL AIRE
A14: Cw=Coef. Aerodinámico | D14: 0.82
A15: A =área de la pieza (m2) | D15: =C9 -> 0.16
A16: p (densidad del aire (Kg/m3) | D16: 1.29
A17: V2 = velocidad del aire 140Km/h (m/s) | D17: 38.89
A18: R (radio de curva) m | D18: 800
A19: K (coeficiente de seguridad) | D19: 3
A21: FUERZAS QUE ACTUAN SOBRE LA PIEZA (N)
A22: Peso | B22: Fuerza de frenado | C22: Resistencia aerodinámica | D22: Fuerza centrífuga | E22: Suma de fuerzas
A23: =C6*9.81 -> 4.905 | B23: =C6*10 -> 5 | C23: =0.5*D14*D15*D16*D17*D17 -> 127.98805 | D23: =C6*((D17*D17)/D18) -> 0.94527006 | E23: =SUM(A23:D23) -> 138.83832
A25: La fuerza de diseño soportada por los anclajes (N) | C25: Fuerza máxima que soportan los tronillos a tracción (N) | D25: Fuerza máxima que soportan los tronillos a cortante (N) | E25: comprobación <= 1
A26: =E23*D19 -> 416.51497 | C26: =((0.9*F10*F9)/1.25)*F6 -> 11746.944 | D26: =((0.5*F10*F9)/1.25)*F6 -> 6526.08 | E26: =(A26/D26)+(A26/(1.4*C26)) -> 0.089149795
A45: Peso de la pieza en Kg | C45: 0.5
A46: Anchura de la pieza en m | C46: 0.4
A47: Altura de la pieza en m | C47: 0.15
A48: Superficie frontal m2 | C48: =C46*C47 -> 0.06
A49: Coef. aerodinámico | C49: 0.82
F50: 24525 | G50: N/CM2
A51: SUJECIÓN
A53: nº tornillos | C53: 12 | G53: =F50/9.81 -> 2500
A54: Métrica | C54: 4
A55: Calidad | C55: BAJA CALIDAD
A56: As( Sección resistente) | C56: 11.33
A57: Res. Tracción Mín tornillo DIN7981: | C57: 25 | D57: Kg/mm2
A59: CARACTERÍSTICAS PARA FUERZA PRODUCIDA POR PRESIÓN DEL AIRE
A61: Cw (Coef. Aerodinámico) | C61: 0.82
A62: A (área de la pieza) | C62: =C48 -> 0.06 | D62: m2
A63: p (densidad del aire) | C63: 1.29 | D63: Kg/m3
A64: V2 (velocidad del aire 140Km/h) | C64: 38.89 | D64: m/s
A65: R (radio de curva) | C65: 800 | D65: m
A66: K (coeficiente de seguridad) | C66: 3
B84: P= | C84: =C45*9.81 -> 4.905 | D84: N
B95: F(fr)= | C95: =C45*10 -> 5 | D95: N
...

Sheet SNORKEL
C2: SNORKEL
A5: CARACTERÍSTICAS DE LA PIEZA | D5: SUJECIÓN
A6: Peso de la pieza en Kg | C6: 12 | D6: nº tornillos | F6: 6
A7: Anchura de la pieza en m | C7: 1.13 | D7: Métrica | F7: S
A8: Altura de la pieza en m | C8: 1.17 | D8: Calidad | F8: 8.8
A9: Superficie frontal m2 | C9: =C7*C8 -> 1.3221 | D9: As( Sección resistente) | F9: 36.64
A10: Coef. aerodinámico | C10: 0.82 | D10: Res. Tracción Mín tornillo 8,8 (Kg/mm2) | F10: 80
A13: CARACTERÍSTICAS PARA FUERZA PRODUCIDA POR PRESIÓN DEL AIRE
A14: Cw=Coef. Aerodinámico | D14: 0.82
A15: A =área de la pieza (m2) | D15: =C9 -> 1.3221
A16: p (densidad del aire (Kg/m3) | D16: 1.29
A17: V2 = velocidad del aire 140Km/h (m/s) | D17: 38.89
A18: R (radio de curva) m | D18: 800
A19: K (coeficiente de seguridad) | D19: 3
A21: FUERZAS QUE ACTUAN SOBRE LA PIEZA (N)
A22: Peso | B22: Fuerza de frenado | C22: Resistencia aerodinámica | D22: Fuerza centrífuga | E22: Suma de fuerzas
A23: =C6*9.81 -> 117.72 | B23: =C6*10 -> 120 | C23: =0.5*D14*D15*D16*D17*D17 -> 1057.5813 | D23: =C6*((D17*D17)/D18) -> 22.686481 | E23: =SUM(A23:D23) -> 1317.9878
A25: La fuerza de diseño soportada por los anclajes (N) | C25: Fuerza máxima que soportan los tronillos a tracción (N) | D25: Fuerza máxima que soportan los tronillos a cortante (N) | E25: comprobación <= 1
A26: =E23*D19 -> 3953.9633 | C26: =((0.9*F10*F9)/1.25)*F6 -> 12662.784 | D26: =((0.5*F10*F9)/1.25)*F6 -> 7034.88 | E26: =(A26/D26)+(A26/(1.4*C26)) -> 0.7850875
A45: Peso de la pieza en Kg | C45: 0.5
A46: Anchura de la pieza en m | C46: 0.4
A47: Altura de la pieza en m | C47: 0.15
A48: Superficie frontal m2 | C48: =C46*C47 -> 0.06
A49: Coef. aerodinámico | C49: 0.82
F50: 24525 | G50: N/CM2
A51: SUJECIÓN
A53: nº tornillos | C53: 12 | G53: =F50/9.81 -> 2500
A54: Métrica | C54: 4
A55: Calidad | C55: BAJA CALIDAD
A56: As( Sección resistente) | C56: 11.33
A57: Res. Tracción Mín tornillo DIN7981: | C57: 25 | D57: Kg/mm2
A59: CARACTERÍSTICAS PARA FUERZA PRODUCIDA POR PRESIÓN DEL AIRE
A61: Cw (Coef. Aerodinámico) | C61: 0.82
A62: A (área de la pieza) | C62: =C48 -> 0.06 | D62: m2
A63: p (densidad del aire) | C63: 1.29 | D63: Kg/m3
A64: V2 (velocidad del aire 140Km/h) | C64: 38.89 | D64: m/s
A65: R (radio de curva) | C65: 800 | D65: m
A66: K (coeficiente de seguridad) | C66: 3
B84: P= | C84: =C45*9.81 -> 4.905 | D84: N
B95: F(fr)= | C95: =C45*10 -> 5 | D95: N
...

Sheet CABRESTANTE
A3: CABRESTANTE
A6: Características del material y elementos de unión empleados
A7: Tiro máx. del cabestrante (Kg) | B7: 6120
A8: Diámetro de cada perno (cm) | B8: 1
A9: Material del perno | B9: Acero 8.8
A10: Tensión min., rotura cortante acero ( Kg/cm2) | B10: 3100
A12: Tensión cortante soportada por los pernos de unión al chasis
A13: Número de penos | B13: 4
A14: Diámetro de cada perno | B14: 10 mm
A15: Material del perno | B15: Acero 8.8
A16: Tensión min., rotura cortante acero | B16: 3.100 Kg/cm2
A17: Tensión cortante ejercida por el tiro del cabrestante sobre los pernos de unión a la estructura de soporte de éste (Kg/cm2) | B17: =D29 -> 1948.0565
A19: Coeficiente de seguridad | B19: =E30 -> 1.5913296
A27: Tc = Tiro de cabrestante / Sección de los pernos. | B27: TC= | C27: tensión máx del cabestrante dividido por la sección de los pernos por el nº de pernos
A28: Tc= 6120 / [(π. R2).4] = 6120 / 4,71 =2604 Kg/cm2
C29: Tc= | D29: =B7/(PI()*(B8/2*B8/2)*B13) -> 1948.0565
A30: La tensión cortante de rotura es inferior a la mínima tensión cortante de los pernos obteniendo un coeficiente de seguridad para el material de 1,19 y considerando esta dirección técnica que es suficiente para la aplicación de cargas a realizar. | C30: COEF. SEGURIDAD | E30: =B10/D29 -> 1.5913296

Sheet SOPORTES LUCES DE TRABAJO
B2: SOPORTES LUCES DE TRABAJO
A5: CARACTERÍSTICAS DE LA PIEZA | D5: SUJECIÓN
A6: Peso de la pieza en Kg | C6: 0.5 | D6: nº tornillos | F6: 4
A7: Anchura de la pieza en m | C7: 0.125 | D7: Métrica | F7: 4
A8: Altura de la pieza en m | C8: 0.065 | D8: Calidad | F8: 8.8
A9: Superficie frontal m2 | C9: =C7*C8 -> 0.008125 | D9: As( Sección resistente) | F9: 8.78
A10: Coef. aerodinámico | C10: 0.82 | D10: Res. Tracción Mín tornillo 8,8 (Kg/mm2) | F10: 80
A13: CARACTERÍSTICAS PARA FUERZA PRODUCIDA POR PRESIÓN DEL AIRE
A14: Cw=Coef. Aerodinámico | D14: 0.82
A15: A =área de la pieza (m2) | D15: =C9 -> 0.008125
A16: p (densidad del aire (Kg/m3) | D16: 1.29
A17: V2 = velocidad del aire 140Km/h (m/s) | D17: 38.89
A18: R (radio de curva) m | D18: 800
A19: K (coeficiente de seguridad) | D19: 3
A21: FUERZAS QUE ACTUAN SOBRE LA PIEZA (N)
A22: Peso | B22: Fuerza de frenado | C22: Resistencia aerodinámica | D22: Fuerza centrífuga | E22: Suma de fuerzas
A23: =C6*9.81 -> 4.905 | B23: =C6*10 -> 5 | C23: =0.5*D14*D15*D16*D17*D17 -> 6.4993934 | D23: =C6*((D17*D17)/D18) -> 0.94527006 | E23: =SUM(A23:D23) -> 17.349663
A25: La fuerza de diseño soportada por los anclajes (N) | C25: Fuerza máxima que soportan los tronillos a tracción (N) | D25: Fuerza máxima que soportan los tronillos a cortante (N) | E25: comprobación <= 1
A26: =E23*D19 -> 52.04899 | C26: =((0.9*F10*F9)/1.25)*F6 -> 2022.912 | D26: =((0.5*F10*F9)/1.25)*F6 -> 1123.84 | E26: =(A26/D26)+(A26/(1.4*C26)) -> 0.064691906
A45: Peso de la pieza en Kg | C45: 0.5
A46: Anchura de la pieza en m | C46: 0.4
A47: Altura de la pieza en m | C47: 0.15
A48: Superficie frontal m2 | C48: =C46*C47 -> 0.06
A49: Coef. aerodinámico | C49: 0.82
F50: 24525 | G50: N/CM2
A51: SUJECIÓN
A53: nº tornillos | C53: 12 | G53: =F50/9.81 -> 2500
A54: Métrica | C54: 4
A55: Calidad | C55: BAJA CALIDAD
A56: As( Sección resistente) | C56: 11.33
A57: Res. Tracción Mín tornillo DIN7981: | C57: 25 | D57: Kg/mm2
A59: CARACTERÍSTICAS PARA FUERZA PRODUCIDA POR PRESIÓN DEL AIRE
A61: Cw (Coef. Aerodinámico) | C61: 0.82
A62: A (área de la pieza) | C62: =C48 -> 0.06 | D62: m2
A63: p (densidad del aire) | C63: 1.29 | D63: Kg/m3
A64: V2 (velocidad del aire 140Km/h) | C64: 38.89 | D64: m/s
A65: R (radio de curva) | C65: 800 | D65: m
A66: K (coeficiente de seguridad) | C66: 3
B84: P= | C84: =C45*9.81 -> 4.905 | D84: N
B95: F(fr)= | C95: =C45*10 -> 5 | D95: N
...

Sheet LUCES INCRUSTADAS EN PARAGOLPES
B2: LUCES INCRUSTADAS
A5: CARACTERÍSTICAS DE LA PIEZA | D5: SUJECIÓN
A6: Peso de la pieza en Kg | C6: 0.1 | D6: nº tornillos | F6: 2
A7: Anchura de la pieza en m | C7: 0.06 | D7: Métrica | F7: 4
A8: Altura de la pieza en m | C8: 0.035 | D8: Calidad | F8: 8.8
A9: Superficie frontal m2 | C9: =C7*C8 -> 0.0021 | D9: As( Sección resistente) | F9: 8.78
A10: Coef. aerodinámico | C10: 0.82 | D10: Res. Tracción Mín tornillo 8,8 (Kg/mm2) | F10: 80
A13: CARACTERÍSTICAS PARA FUERZA PRODUCIDA POR PRESIÓN DEL AIRE
A14: Cw=Coef. Aerodinámico | D14: 0.82
A15: A =área de la pieza (m2) | D15: =C9 -> 0.0021
A16: p (densidad del aire (Kg/m3) | D16: 1.29
A17: V2 = velocidad del aire 140Km/h (m/s) | D17: 38.89
A18: R (radio de curva) m | D18: 800
A19: K (coeficiente de seguridad) | D19: 3
A21: FUERZAS QUE ACTUAN SOBRE LA PIEZA (N)
A22: Peso | B22: Fuerza de frenado | C22: Resistencia aerodinámica | D22: Fuerza centrífuga | E22: Suma de fuerzas
A23: =C6*9.81 -> 0.981 | B23: =C6*10 -> 1 | C23: =0.5*D14*D15*D16*D17*D17 -> 1.6798432 | D23: =C6*((D17*D17)/D18) -> 0.18905401 | E23: =SUM(A23:D23) -> 3.8498972
A25: La fuerza de diseño soportada por los anclajes (N) | C25: Fuerza máxima que soportan los tronillos a tracción (N) | D25: Fuerza máxima que soportan los tronillos a cortante (N) | E25: comprobación <= 1
A26: =E23*D19 -> 11.549692 | C26: =((0.9*F10*F9)/1.25)*F6 -> 1011.456 | D26: =((0.5*F10*F9)/1.25)*F6 -> 561.92 | E26: =(A26/D26)+(A26/(1.4*C26)) -> 0.028710319
A45: Peso de la pieza en Kg | C45: 0.5
A46: Anchura de la pieza en m | C46: 0.4
A47: Altura de la pieza en m | C47: 0.15
A48: Superficie frontal m2 | C48: =C46*C47 -> 0.06
A49: Coef. aerodinámico | C49: 0.82
F50: 24525 | G50: N/CM2
A51: SUJECIÓN
A53: nº tornillos | C53: 12 | G53: =F50/9.81 -> 2500
A54: Métrica | C54: 4
A55: Calidad | C55: BAJA CALIDAD
A56: As( Sección resistente) | C56: 11.33
A57: Res. Tracción Mín tornillo DIN7981: | C57: 25 | D57: Kg/mm2
A59: CARACTERÍSTICAS PARA FUERZA PRODUCIDA POR PRESIÓN DEL AIRE
A61: Cw (Coef. Aerodinámico) | C61: 0.82
A62: A (área de la pieza) | C62: =C48 -> 0.06 | D62: m2
A63: p (densidad del aire) | C63: 1.29 | D63: Kg/m3
A64: V2 (velocidad del aire 140Km/h) | C64: 38.89 | D64: m/s
A65: R (radio de curva) | C65: 800 | D65: m
A66: K (coeficiente de seguridad) | C66: 3
B84: P= | C84: =C45*9.81 -> 4.905 | D84: N
B95: F(fr)= | C95: =C45*10 -> 5 | D95: N
...

Sheet PARAGOLPES DELANTERO
B2: PARAGOLPES DELANTERO
A5: CARACTERÍSTICAS DE LA PIEZA | D5: SUJECIÓN
A6: Peso de la pieza en Kg | C6: 2 | D6: nº tornillos | F6: 8
A7: Anchura de la pieza en m | C7: 0.53 | D7: Métrica | F7: 8
A8: Altura de la pieza en m | C8: 0.83 | D8: Calidad | F8: 8.8
A9: Superficie frontal m2 | C9: =C7*C8 -> 0.4399 | D9: As( Sección resistente) | F9: 36.63
A10: Coef. aerodinámico | C10: 0.82 | D10: Res. Tracción Mín tornillo 8,8 (Kg/mm2) | F10: 80
A13: CARACTERÍSTICAS PARA FUERZA PRODUCIDA POR PRESIÓN DEL AIRE
A14: Cw=Coef. Aerodinámico | D14: 0.82
A15: A =área de la pieza (m2) | D15: =C9 -> 0.4399
A16: p (densidad del aire (Kg/m3) | D16: 1.29
A17: V2 = velocidad del aire 140Km/h (m/s) | D17: 38.89
A18: R (radio de curva) m | D18: 800
A19: K (coeficiente de seguridad) | D19: 3 | H19: projectesxalo
A21: FUERZAS QUE ACTUAN SOBRE LA PIEZA (N)
A22: Peso | B22: Fuerza de frenado | C22: Resistencia aerodinámica | D22: Fuerza centrífuga | E22: Suma de fuerzas
A23: =C6*9.81 -> 19.62 | B23: =C6*10 -> 20 | C23: =0.5*D14*D15*D16*D17*D17 -> 351.88716 | D23: =C6*((D17*D17)/D18) -> 3.7810803 | E23: =SUM(A23:D23) -> 395.28824
A25: La fuerza de diseño soportada por los anclajes (N) | C25: Fuerza máxima que soportan los tronillos a tracción (N) | D25: Fuerza máxima que soportan los tronillos a cortante (N) | E25: comprobación <= 1
A26: =E23*D19 -> 1185.8647 | C26: =((0.9*F10*F9)/1.25)*F6 -> 16879.104 | D26: =((0.5*F10*F9)/1.25)*F6 -> 9377.28 | E26: =(A26/D26)+(A26/(1.4*C26)) -> 0.17664461
A45: Peso de la pieza en Kg | C45: 0.5
A46: Anchura de la pieza en m | C46: 0.4
A47: Altura de la pieza en m | C47: 0.15
A48: Superficie frontal m2 | C48: =C46*C47 -> 0.06
A49: Coef. aerodinámico | C49: 0.82
F50: 24525 | G50: N/CM2
A51: SUJECIÓN
A53: nº tornillos | C53: 12 | G53: =F50/9.81 -> 2500
A54: Métrica | C54: 4
A55: Calidad | C55: BAJA CALIDAD
A56: As( Sección resistente) | C56: 11.33
A57: Res. Tracción Mín tornillo DIN7981: | C57: 25 | D57: Kg/mm2
A59: CARACTERÍSTICAS PARA FUERZA PRODUCIDA POR PRESIÓN DEL AIRE
A61: Cw (Coef. Aerodinámico) | C61: 0.82
A62: A (área de la pieza) | C62: =C48 -> 0.06 | D62: m2
A63: p (densidad del aire) | C63: 1.29 | D63: Kg/m3
A64: V2 (velocidad del aire 140Km/h) | C64: 38.89 | D64: m/s
A65: R (radio de curva) | C65: 800 | D65: m
A66: K (coeficiente de seguridad) | C66: 3
B84: P= | C84: =C45*9.81 -> 4.905 | D84: N
B95: F(fr)= | C95: =C45*10 -> 5 | D95: N
...

Sheet PARAGOLPES TRASERO
B2: PARAGOLPES TRASERO
A5: CARACTERÍSTICAS DE LA PIEZA | D5: SUJECIÓN
A6: Peso de la pieza en Kg | C6: 1.5 | D6: nº tornillos | F6: 6
A7: Anchura de la pieza en m | C7: 0.43 | D7: Métrica | F7: 8
A8: Altura de la pieza en m | C8: 0.33 | D8: Calidad | F8: 8.8
A9: Superficie frontal m2 | C9: =C7*C8 -> 0.1419 | D9: As( Sección resistente) | F9: 36.63
A10: Coef. aerodinámico | C10: 0.82 | D10: Res. Tracción Mín tornillo 8,8 (Kg/mm2) | F10: 80
A13: CARACTERÍSTICAS PARA FUERZA PRODUCIDA POR PRESIÓN DEL AIRE
A14: Cw=Coef. Aerodinámico | D14: 0.82
A15: A =área de la pieza (m2) | D15: =C9 -> 0.1419
A16: p (densidad del aire (Kg/m3) | D16: 1.29
A17: V2 = velocidad del aire 140Km/h (m/s) | D17: 38.89
A18: R (radio de curva) m | D18: 800
A19: K (coeficiente de seguridad) | D19: 3
A21: FUERZAS QUE ACTUAN SOBRE LA PIEZA (N)
A22: Peso | B22: Fuerza de frenado | C22: Resistencia aerodinámica | D22: Fuerza centrífuga | E22: Suma de fuerzas
A23: =C6*9.81 -> 14.715 | B23: =C6*10 -> 15 | C23: =0.5*D14*D15*D16*D17*D17 -> 113.50941 | D23: =C6*((D17*D17)/D18) -> 2.8358102 | E23: =SUM(A23:D23) -> 146.06022
A25: La fuerza de diseño soportada por los anclajes (N) | C25: Fuerza máxima que soportan los tronillos a tracción (N) | D25: Fuerza máxima que soportan los tronillos a cortante (N) | E25: comprobación <= 1
A26: =E23*D19 -> 438.18065 | C26: =((0.9*F10*F9)/1.25)*F6 -> 12659.328 | D26: =((0.5*F10*F9)/1.25)*F6 -> 7032.96 | E26: =(A26/D26)+(A26/(1.4*C26)) -> 0.087027632
A45: Peso de la pieza en Kg | C45: 0.5
A46: Anchura de la pieza en m | C46: 0.4
A47: Altura de la pieza en m | C47: 0.15
A48: Superficie frontal m2 | C48: =C46*C47 -> 0.06
A49: Coef. aerodinámico | C49: 0.82
F50: 24525 | G50: N/CM2
A51: SUJECIÓN
A53: nº tornillos | C53: 12 | G53: =F50/9.81 -> 2500
A54: Métrica | C54: 4
A55: Calidad | C55: BAJA CALIDAD
A56: As( Sección resistente) | C56: 11.33
A57: Res. Tracción Mín tornillo DIN7981: | C57: 25 | D57: Kg/mm2
A59: CARACTERÍSTICAS PARA FUERZA PRODUCIDA POR PRESIÓN DEL AIRE
A61: Cw (Coef. Aerodinámico) | C61: 0.82
A62: A (área de la pieza) | C62: =C48 -> 0.06 | D62: m2
A63: p (densidad del aire) | C63: 1.29 | D63: Kg/m3
A64: V2 (velocidad del aire 140Km/h) | C64: 38.89 | D64: m/s
A65: R (radio de curva) | C65: 800 | D65: m
A66: K (coeficiente de seguridad) | C66: 3
B84: P= | C84: =C45*9.81 -> 4.905 | D84: N
B95: F(fr)= | C95: =C45*10 -> 5 | D95: N
...

Sheet ESTRIBOS LATERALES
B2: ESTRIBOS LATERALES
A5: CARACTERÍSTICAS DE LA PIEZA | D5: SUJECIÓN
A6: Peso de la pieza en Kg | C6: 90 | D6: nº tornillos | F6: 6
A7: Anchura de la pieza en m | C7: 0.85 | D7: Métrica | F7: 10
A8: Altura de la pieza en m | C8: 0.15 | D8: Calidad | F8: 8.8
A9: Superficie frontal m2 | C9: =C7*C8 -> 0.1275 | D9: As( Sección resistente) | F9: 58.03
A10: Coef. aerodinámico | C10: 0.82 | D10: Res. Tracción Mín tornillo 8,8 (Kg/mm2) | F10: 80
A13: CARACTERÍSTICAS PARA FUERZA PRODUCIDA POR PRESIÓN DEL AIRE
A14: Cw=Coef. Aerodinámico | D14: 0.82
A15: A =área de la pieza (m2) | D15: =C9 -> 0.1275
A16: p (densidad del aire (Kg/m3) | D16: 1.29
A17: V2 = velocidad del aire 140Km/h (m/s) | D17: 38.89
A18: R (radio de curva) m | D18: 800
A19: K (coeficiente de seguridad) | D19: 3
A21: FUERZAS QUE ACTUAN SOBRE LA PIEZA (N)
A22: Peso | B22: Fuerza de frenado | C22: Resistencia aerodinámica | D22: Fuerza centrífuga | E22: Suma de fuerzas
A23: =C6*9.81 -> 882.9 | B23: =C6*10 -> 900 | C23: =0.5*D14*D15*D16*D17*D17 -> 101.99048 | D23: =C6*((D17*D17)/D18) -> 170.14861 | E23: =SUM(A23:D23) -> 2055.0391
A25: La fuerza de diseño soportada por los anclajes (N) | C25: Fuerza máxima que soportan los tronillos a tracción (N) | D25: Fuerza máxima que soportan los tronillos a cortante (N) | E25: comprobación <= 1
A26: =E23*D19 -> 6165.1173 | C26: =((0.9*F10*F9)/1.25)*F6 -> 20055.168 | D26: =((0.5*F10*F9)/1.25)*F6 -> 11141.76 | E26: =(A26/D26)+(A26/(1.4*C26)) -> 0.77291132
A45: Peso de la pieza en Kg | C45: 0.5
A46: Anchura de la pieza en m | C46: 0.4
A47: Altura de la pieza en m | C47: 0.15
A48: Superficie frontal m2 | C48: =C46*C47 -> 0.06
A49: Coef. aerodinámico | C49: 0.82
F50: 24525 | G50: N/CM2
A51: SUJECIÓN
A53: nº tornillos | C53: 12 | G53: =F50/9.81 -> 2500
A54: Métrica | C54: 4
A55: Calidad | C55: BAJA CALIDAD
A56: As( Sección resistente) | C56: 11.33
A57: Res. Tracción Mín tornillo DIN7981: | C57: 25 | D57: Kg/mm2
A59: CARACTERÍSTICAS PARA FUERZA PRODUCIDA POR PRESIÓN DEL AIRE
A61: Cw (Coef. Aerodinámico) | C61: 0.82
A62: A (área de la pieza) | C62: =C48 -> 0.06 | D62: m2
A63: p (densidad del aire) | C63: 1.29 | D63: Kg/m3
A64: V2 (velocidad del aire 140Km/h) | C64: 38.89 | D64: m/s
A65: R (radio de curva) | C65: 800 | D65: m
A66: K (coeficiente de seguridad) | C66: 3
B84: P= | C84: =C45*9.81 -> 4.905 | D84: N
B95: F(fr)= | C95: =C45*10 -> 5 | D95: N
...

Sheet MOBILIARIO INTERIOR CAMPER
B2: CAMPERS
B6: ESFUERZOS LONGITUDINALES
B8: DATOS DE PARTIDA
B9: M.T.M.A. (Kg) | C9: =TOTALES!B17 -> 2000
B10: Velocidad máxima (Km/h) | C10: 148
B11: Coeficiente de rozamiento | C11: 0.6
B12: Aceleración de la gravedad (m/s2) | C12: 9.8
B13: Deesaceleración ar = µ * g (m/s2) | C13: =C11*C12 -> 5.88
B14: Tr = µ * Mt (Kg) | C14: =C9*C11 -> 1200
A19: ESFUERZOS LONGITUDINALES ELEMENTOS INSTALADOS
A20: 1 | B20: Mueble alto 1250x405x325mm | C20: Q1 | D20: 12 | E20: kg
A21: 2 | B21: Mueble alto 1120x390x320mm | C21: Q2 | D21: 12 | E21: kg
A22: 3 | B22: Mueble bajo 1350x1800x900mm | C22: Q3 | D22: 50 | E22: kg
A23: 4 | B23: Mueble bajo 600x1420x900mm | C23: Q4 | D23: 50 | E23: kg
A24: 5 | B24: Mueble bajo 1200x610x580mm | C24: Q5 | D24: 50 | E24: kg
A25: 6 | B25: Armario 1180x320x625mm | C25: Q6 | D25: 15 | E25: kg
A26: 7 | B26: Mueble bajo 1080x610x580mm | C26: Q7 | D26: 50 | E26: kg
A27: 8 | B27: Aseo 1030x2100x590mm | C27: Q8 | D27: 13 | E27: kg
B32: CARACTERISTICAS DE LOS TORNILLOS
B33: Diámetro nominal (mm) | D33: 4 | E33: 5 | F33: 6 | G33: 8
B34: Paso de rosca(mm) | D34: 0.7 | E34: 0.8 | F34: 1 | G34: 1.25
B35: Calidad | D35: UM8.8 | E35: UM8.8 | F35: UM8.8 | G35: UM8.8
B36: Sección de tensión(mm2) | D36: 3.24 | E36: 5.93 | F36: 7.97 | G36: 15.78
B37: Resistencia material (kg/mm2) | D37: 64 | E37: 64 | F37: 64 | G37: 64
B38: Carga máx. en límite elástico (Kg) | D38: 207 | E38: 380 | F38: 510 | G38: 1010
B39: Par de apriete(mm) | D39: 120 | E39: 290 | F39: 1100 | G39: 2600
B40: Radio sección sin roscar(mm) | D40: 2 | E40: 2.5 | F40: 3 | G40: 4
B41: Radio efectivo(mm) | D41: 1.015 | E41: 1.374 | F41: 1.593 | G41: 2.241
A44: NÚMERO DE TORNILLOS UTILIZADOS Y MÉTRICA
A45: Componente / Diámetro tornillo (mm) | C45: 4 | D45: 5 | E45: 6 | F45: 8 | G45: total
A46: =B20 -> Mueble alto 1250x405x325mm | D46: 15 | G46: =SUM(C46:F46) -> 15
A47: =B21 -> Mueble alto 1120x390x320mm | D47: 15 | G47: =SUM(C47:F47) -> 15
A48: =B22 -> Mueble bajo 1350x1800x900mm | D48: 20 | G48: =SUM(C48:F48) -> 20
A49: =B23 -> Mueble bajo 600x1420x900mm | D49: 20 | G49: =SUM(C49:F49) -> 20
A50: =B24 -> Mueble bajo 1200x610x580mm | D50: 20 | G50: =SUM(C50:F50) -> 20
A51: =B25 -> Armario 1180x320x625mm | D51: 15 | G51: =SUM(C51:F51) -> 15
A52: =B26 -> Mueble bajo 1080x610x580mm | D52: 20 | G52: =SUM(C52:F52) -> 20
A53: =B27 -> Aseo 1030x2100x590mm | D53: 12 | G53: =SUM(C53:F53) -> 12
A60: Calidad | C60: M8.8
A61: Resistencia a cortadura (Kg) | C61: 227.8
...

Sheet ESTABILIDAD VEHICULO
D14: Cond. Originales | E14: Cond. Actuales
A15: MMA Total | B15: 2850 | C15: Altura (h) | D15: 1840 | E15: 1932
A16: MMA eje 1 | B16: 1350 | C16: Ancho de vía más desfav. (d): | D16: 1605 | E16: 1415
A17: MMA eje 2 | B17: 1750 | C17: Distancia entre ejes: | D17: 2400 | E17: 2400
A18: Diámetro rueda antes | B18: 777.4 | C18: Tara: | D18: 2315 | E18: 2490
A19: Diámetro rueda después | B19: 830.8 | C19: Carga útil (Qútil): | D19: 160 | E19: 60
C20: Altura al bastidor (hb): | D20: 445 | E20: 535
A85: RESULTADOS | B85: ORIGINAL | C85: ACTUAL
A86: hcu | B86: =((D15-D20)/2)+D20 -> 1142.5 | C86: =((E15-E20)/2)+E20 -> 1233.5
A87: hcg | B87: =(D20*D18+B86*D19)/B15 -> 425.60526 | C87: =((E20*E18)+(C86*E19))/B15 -> 493.38947
A88: Inclinación | B88: =ATAN(D16/(2*B87))*180/PI() -> 62.060791 | C88: =ATAN(E16/(2*C87))*180/PI() -> 55.109227
A170: RESULTADOS | B170: ORIGINAL | C170: ACTUAL
A171: hcg | B171: =B87 -> 425.60526 | C171: =C87 -> 493.38947
A172: Inclinación | B172: =ATAN(B173/B171)*180/PI() -> 69.475356 | C172: =ATAN(C173/C171)*180/PI() -> 66.539156
A173: X | B173: =(B16*D17)/B15 -> 1136.8421 | C173: =(B16*E17)/B15 -> 1136.8421

Sheet ENGANCHE REMOLQUE
A28: D | B28: =B29*(B30*B31)/(B30+B31) -> 12.485455 | C28: KN | F28: R | G28: =G30*G31/(G29*G30-G31) -> 1.751147 | H28: Tn
A29: g | B29: 9.81 | C29: m/s2 | F29: g | G29: 9.81 | H29: m/s2
A30: T=MTMA | B30: 3.5 | C30: Tn | F30: T=MTMA | G30: 3.5 | H30: Tn
A31: R (MMR) | B31: 2 | C31: Tn | F31: D | G31: 11.45 | H31: KN
A32: MTMA | B32: 3.5 | C32: Tn
A33: S | B33: 0.08 | C33: Tn

Sheet FRENOS TAMBOR
A3: FRENO DE TAMBOR
A4: MASA EJE DELANTERO | B4: 1110 | C4: Kg | E4: =B4*9.81 -> 10889.1 | F4: N
A5: Diámetro | B5: ØD | C5: 0.2 | D5: RDET | E5: =C5/2 -> 0.1
A6: Diámetro bomba | C6: 0.0317
A7: Diámetro piston (m) | B7: ØPP | C7: 0.019
A8: Número de pistones | C8: 2
A18: 𝐴𝑙𝑡𝑢𝑟𝑎 𝑑𝑒𝑙 𝑝𝑒𝑑𝑎𝑙 𝑒𝑛 𝑟𝑒𝑝𝑜𝑠𝑜 → ℎ𝑝𝑟 | B18: 0.197
A19: 𝐴𝑙𝑡𝑢𝑟𝑎 𝑑𝑒𝑙 𝑝𝑒𝑑𝑎𝑙 𝑝𝑖𝑠𝑎_xD835_ → | B19: 0.12
A20: 𝐹𝑢𝑒𝑟𝑧𝑎 𝑒𝑗𝑒𝑟𝑐𝑖𝑑𝑎 𝑒𝑛 𝑒𝑙 𝑝𝑒𝑑𝑎𝑙 → 𝐹𝑒𝑝 | B20: 50 | C20: Kg | D20: =B20*9.81 -> 490.5 | E20: N
A21: 𝑅𝑒𝑙𝑎𝑐𝑖ó𝑛 𝑑𝑒 𝑑𝑒𝑠𝑚𝑢𝑙𝑡𝑖𝑝𝑙𝑖𝑐𝑎𝑐𝑖ó𝑛 𝑑𝑒𝑙 𝑝𝑒𝑑𝑎𝑙→ 𝑅𝑝 | B21: 1: | C21: 5
A22: coeficiente de fricción (𝜇𝐹) | C22: 0.3
A23: Radio del neumático | C23: 0.40255 | D23: mm
A26: Se ha mantenido original todo el circuito del líquido de frenos
A28: Una vez conocidos todos los datos, empezamos a realizar los cálculos.
A29: Para conocer la influencia del pedal de freno sobre el sistema, cabe resaltar que el pedal es un elemento amplificador de la fuerza que ejerce el conductor. Las ecuaciones que se muestran a
A30: continuación son para un sistema de frenado sin servofreno. Por lo tanto, para conocer el valor de la fuerza que se ejerce sobre el sistema se emplea la siguiente expresión, donde se
A31: puede apreciar como la fuerza aplicada por el conductor (𝐹𝑒𝑝) se multiplica por la relación del pedal (𝑅𝑝).
A42: Fsp= | B42: =D20*C21 -> 2452.5 | C42: N
B51: =B42/(PI()*(C6/2)*(C6/2)) -> 3107424.7 | C51: N/m2
A85: FPT= | B85: =C8*B51*(PI()*(C7/2)^2) -> 1762.0884 | C85: N
A99: coeficiente de fricción (𝜇𝐹)=0,3
A100: FR=864991,685
A102: CA= | B102: 1.2 | C102: (del diagrama para (𝜇𝐹)=0,3 y freno simplex
A104: Fperiferica= | B104: =B102*B85 -> 2114.5061 | C104: N
A120: FFR= | B120: =B104*E5/C23 -> 525.27787 | C120: N
A131: FTF= | B131: =2*B120 -> 1050.5557 | C131: N

Sheet FRENOS DISCO
A3: FRENO DE DISCO
A4: MASA EJE DELANTERO | B4: 1110 | C4: Kg | E4: =B4*9.81 -> 10889.1 | F4: N
A5: Diámetro exterior (m) | B5: ØDET | C5: 0.294 | D5: RDET | E5: =C5/2 -> 0.147
A6: Diámetro interior (m) | B6: ØDIT | C6: 0.24 | D6: RDIT | E6: =C6/2 -> 0.12
A7: Diámetro bomba | C7: 0.0317
A8: Diámetro piston (m) | B8: ØPP | C8: 0.045
A9: Número de pistones | C9: 1
A10: Ángulo de contacto entre pastilla y disco rad | C10: 0.7
A15: Radio efectivo | B15: =E6+(E5-E6)/2 -> 0.1335
A21: 𝐴𝑙𝑡𝑢𝑟𝑎 𝑑𝑒𝑙 𝑝𝑒𝑑𝑎𝑙 𝑒𝑛 𝑟𝑒𝑝𝑜𝑠𝑜 → ℎ𝑝𝑟 | B21: 0.197
A22: 𝐴𝑙𝑡𝑢𝑟𝑎 𝑑𝑒𝑙 𝑝𝑒𝑑𝑎𝑙 𝑝𝑖𝑠𝑎_xD835_ → | B22: 0.12
A23: 𝐹𝑢𝑒𝑟𝑧𝑎 𝑒𝑗𝑒𝑟𝑐𝑖𝑑𝑎 𝑒𝑛 𝑒𝑙 𝑝𝑒𝑑𝑎𝑙 → 𝐹𝑒𝑝 | B23: 50 | C23: Kg | D23: =B23*9.81 -> 490.5 | E23: N
A24: 𝑅𝑒𝑙𝑎𝑐𝑖ó𝑛 𝑑𝑒 𝑑𝑒𝑠𝑚𝑢𝑙𝑡𝑖𝑝𝑙𝑖𝑐𝑎𝑐𝑖ó𝑛 𝑑𝑒𝑙 𝑝𝑒𝑑𝑎𝑙→ 𝑅𝑝 | B24: 1: | C24: 5
A25: coeficiente de fricción que hay entre el disco y la pastilla (𝜇𝐹) | C25: 0.4
A26: Radio del neumático | C26: 0.40255 | D26: mm
A29: Se ha mantenido original todo el circuito del líquido de frenos
A31: Una vez conocidos todos los datos, empezamos a realizar los cálculos.
A32: Para conocer la influencia del pedal de freno sobre el sistema, cabe resaltar que el pedal es un elemento amplificador de la fuerza que ejerce el conductor. Las ecuaciones que se muestran a
A33: continuación son para un sistema de frenado sin servofreno. Por lo tanto, para conocer el valor de la fuerza que se ejerce sobre el sistema se emplea la siguiente expresión, donde se
A34: puede apreciar como la fuerza aplicada por el conductor (𝐹𝑒𝑝) se multiplica por la relación del pedal (𝑅𝑝).
A45: Fsp= | B45: =D23*C24 -> 2452.5 | C45: N
B54: =B45/(PI()*(C7/2)*(C7/2)) -> 3107424.7 | C54: N/m2
A86: FPT= | B86: =C9*B54*(PI()*C8/2*C8/2) -> 4942.1454 | C86: N
A100: FFF= | B100: =B86*C25 -> 1976.8582 | C100: N
A105: Como tenemos dos discos en el eje trasero | B105: FTFF= | C105: 2*FFF | D105: =2*B100 -> 3953.7163 | E105: N
A117: NF= | B117: =2*B100*B15 -> 527.82113 | C117: Nm
A135: FFRT= | B135: =B117/C26 -> 1311.194 | C135: N
A144: FTF= | B144: =2*B135 -> 2622.3879 | C144: N

Sheet PRESUPUESTO PROYECTO
B1: Presupuesto
A8: CONCEPTO | D8: EUROS
A9: Materiales usados en la reforma | D9: 3215
A10: Mano de obra | D10: 1050
A11: Total presupuesto | D11: =D9+D10 -> 4265
